Workbook

Sheet Diagnostic Report
A1: Parameter Diagnostic Report — What Was Fixed and Why
A2: Checks: (1) m_i vs M_i reachability (2) breakeven weeks vs shelf life (3) discount saving direction (4) M_i set correctly per proposal formula
A4: Instance | B4: Ingredient | C4: Check | D4: Old value | E4: New value | F4: Status before | G4: Status after | H4: Explanation
A5: Instance 1 | B5: Tomato | C5: m_i vs M_i | D5: m=200 | E5: m=90 | F5: ⚠ m>M_i (200>100) | G5: ✓ Fixed | H5: Max weekly demand = 100 units; m was 2× that so discount was structurally impossible. Set m=90 so discount activates in weeks with demand ≥90.
A6: Instance 1 | B6: Egg | C6: m_i vs M_i | D6: m=300 | E6: m=150 | F6: ⚠ m>M_i (300>170) | G6: ✓ Fixed | H6: M_i over 2 weeks = 170 units max. m=300 was unreachable. Set m=150 (reachable by buying ahead into week 2).
A7: Instance 1 | B7: Chicken Leg | C7: breakeven vs L | D7: h=0.20 | E7: h=0.18 | F7: ⚠ breakeven=2.5 > L=2 | G7: ✓ Fixed | H7: Saving/unit=0.50, h=0.20 → breakeven=2.5 wks but L=2. Reduced h slightly so discount is marginally incentivised.
A8: Instance 3 | B8: Chicken Leg | C8: breakeven vs L | D8: h=0.05 | E8: h=0.55 | F8: ⚠ breakeven=30 >> L=3 | G8: ✓ Fixed | H8: Saving=1.50, h=0.05 → breakeven=30 wks; no realistic incentive to hold. Increased h so breakeven=2.7 wks, well within L=3.
A9: Instance 3 | B9: Tomato | C9: breakeven vs L | D9: h=0.02 | E9: h=0.20 | F9: ⚠ breakeven=15 >> L=2 | G9: ✓ Fixed | H9: Saving=0.30, h=0.02 → breakeven=15 wks. Holding cost raised so breakeven=1.5 wks < L=2.
A10: Instance 3 | B10: Egg | C10: breakeven vs L | D10: h=0.01 | E10: h=0.10 | F10: ⚠ breakeven=15 >> L=3 | G10: ✓ Fixed | H10: Saving=0.15, h=0.01 → breakeven=15 wks. Raised h so breakeven=1.5 wks < L=3.
A11: Instance 3 | B11: Spinach | C11: breakeven vs L | D11: h=0.02 | E11: h=0.18 | F11: ⚠ breakeven=12.5 >> L=2 | G11: ✓ Fixed | H11: Saving=0.25, h=0.02 → breakeven=12.5 wks. Raised h so breakeven=1.4 wks < L=2.
A12: Instance 4 | B12: Tomato | C12: m_i vs M_i | D12: m=200 | E12: m=65 | F12: ⚠ m>M_i (200>70) | G12: ✓ Fixed | H12: Flat demand = 70 units/wk; L=1 so M_i=70. m=65 creates a meaningful discount decision each week.
A13: Instance 4 | B13: Egg | C13: m_i vs M_i | D13: m=300 | E13: m=130 | F13: ⚠ m>M_i (300>140) | G13: ✓ Fixed | H13: M_i over 2 weeks = 140. m=130 is reachable by buying 2 weeks ahead; tests the carryover–discount interaction.
A14: Instance 4 | B14: Spinach | C14: m_i vs M_i | D14: m=150 | E14: m=95 | F14: ⚠ m>M_i (150>100) | G14: ✓ Fixed | H14: Flat demand=100 units/wk; L=1 so M_i=100. m=95 makes discount narrowly reachable for sensitivity testing.
A15: Instance 5 | B15: Rice | C15: M_i value | D15: Not set | E15: M=765 | F15: M_i unverified | G15: ✓ Confirmed | H15: M_i = max cumulative demand over L=3 consecutive weeks = wk1+wk2+wk3 = 220+240+260=720. m=500 is safely below M_i=720. No change needed.
A16: All | B16: All L=1 ingr. | C16: Breakeven note | D16: — | E16: — | F16: Holding>saving | G16: Note only | H16: For L=1 ingredients, holding cost is irrelevant (nothing can be carried over). Breakeven check only matters when L≥2. No fix needed for L=1 items.

Sheet Parameter Checks
A1: Parameter Consistency Checks — All Instances
A2: Green = OK | Amber = borderline | Red = structural problem | Breakeven check only meaningful when L ≥ 2
A4: Instance | B4: Ingredient | C4: L | D4: m_i | E4: M_i (formula) | F4: m_i/M_i | G4: Saving/unit | H4: Breakeven (wks) | I4: Status: m vs M | J4: Status: breakeven | K4: Verdict
A5: Instance 1 (Base) | B5: Chicken Leg | C5: 2 | D5: 100 | E5: 170 | F5: 0.59 | G5: 0.5 | H5: 2.8 | I5: ✓ 0.59 | J5: ⚠ 2.8wks > L=2 | K5: ⚠ Review
B6: Tomato | C6: 1 | D6: 90 | E6: 100 | F6: 0.90 | G6: 0.15 | H6: 3 | I6: ✓ 0.90 | J6: N/A (L=1) | K6: ✓ OK
B7: Egg | C7: 2 | D7: 150 | E7: 170 | F7: 0.88 | G7: 0.06 | H7: 3 | I7: ✓ 0.88 | J7: ⚠ 3.0wks > L=2 | K7: ⚠ Review
B8: Spinach | C8: 1 | D8: 150 | E8: 180 | F8: 0.83 | G8: 0.06 | H8: 2 | I8: ✓ 0.83 | J8: N/A (L=1) | K8: ✓ OK
A9: Instance 2 (No Discount) | B9: Chicken Leg | C9: 1 | D9: 200 | E9: 25 | F9: 8.00 | G9: 0.5 | H9: 2.5 | I9: ⚠ 8.00 | J9: N/A (L=1) | K9: Note: L=1
B10: Tomato | C10: 1 | D10: 400 | E10: 40 | F10: 10.00 | G10: 0.15 | H10: 3 | I10: ⚠ 10.00 | J10: N/A (L=1) | K10: Note: L=1
B11: Egg | C11: 1 | D11: 600 | E11: 40 | F11: 15.00 | G11: 0.06 | H11: 3 | I11: ⚠ 15.00 | J11: N/A (L=1) | K11: Note: L=1
B12: Spinach | C12: 1 | D12: 300 | E12: 70 | F12: 4.29 | G12: 0.06 | H12: 2 | I12: ⚠ 4.29 | J12: N/A (L=1) | K12: Note: L=1
A13: Instance 3 (Carryover) | B13: Chicken Leg | C13: 3 | D13: 100 | E13: 195 | F13: 0.51 | G13: 1.5 | H13: 2.7 | I13: ✓ 0.51 | J13: ✓ 2.7wks | K13: ✓ OK
B14: Tomato | C14: 2 | D14: 100 | E14: 140 | F14: 0.71 | G14: 0.3 | H14: 1.5 | I14: ✓ 0.71 | J14: ✓ 1.5wks | K14: ✓ OK
B15: Egg | C15: 3 | D15: 150 | E15: 260 | F15: 0.58 | G15: 0.15 | H15: 1.5 | I15: ✓ 0.58 | J15: ✓ 1.5wks | K15: ✓ OK
B16: Spinach | C16: 2 | D16: 80 | E16: 180 | F16: 0.44 | G16: 0.25 | H16: 1.4 | I16: ✓ 0.44 | J16: ✓ 1.4wks | K16: ✓ OK
A17: Instance 4 (Sensitivity) | B17: Chicken Leg | C17: 2 | D17: 100 | E17: 120 | F17: 0.83 | G17: 0.5 | H17: 2.8 | I17: ✓ 0.83 | J17: ⚠ 2.8wks > L=2 | K17: ⚠ Review
B18: Tomato | C18: 1 | D18: 65 | E18: 70 | F18: 0.93 | G18: 0.15 | H18: 3 | I18: ✓ 0.93 | J18: N/A (L=1) | K18: ✓ OK
B19: Egg | C19: 2 | D19: 130 | E19: 140 | F19: 0.93 | G19: 0.06 | H19: 3 | I19: ✓ 0.93 | J19: ⚠ 3.0wks > L=2 | K19: ⚠ Review
B20: Spinach | C20: 1 | D20: 95 | E20: 100 | F20: 0.95 | G20: 0.06 | H20: 2 | I20: ✓ 0.95 | J20: N/A (L=1) | K20: ✓ OK
A21: Instance 5 (Large) | B21: Chicken | C21: 2 | D21: 200 | E21: 485 | F21: 0.41 | G21: 0.65 | H21: 3.6 | I21: ✓ 0.41 | J21: ⚠ 3.6wks > L=2 | K21: ⚠ Review
B22: Beef | C22: 2 | D22: 150 | E22: 340 | F22: 0.44 | G22: 0.9 | H22: 4.1 | I22: ✓ 0.44 | J22: ⚠ 4.1wks > L=2 | K22: ⚠ Review
B23: Tomato | C23: 1 | D23: 300 | E23: 365 | F23: 0.82 | G23: 0.18 | H23: 4.5 | I23: ✓ 0.82 | J23: N/A (L=1) | K23: ✓ OK
B24: Spinach | C24: 1 | D24: 200 | E24: 345 | F24: 0.58 | G24: 0.14 | H24: 4.7 | I24: ✓ 0.58 | J24: N/A (L=1) | K24: ✓ OK
B25: Egg | C25: 2 | D25: 400 | E25: 550 | F25: 0.73 | G25: 0.08 | H25: 4 | I25: ✓ 0.73 | J25: ⚠ 4.0wks > L=2 | K25: ⚠ Review
B26: Rice | C26: 3 | D26: 500 | E26: 765 | F26: 0.65 | G26: 0.06 | H26: 6 | I26: ✓ 0.65 | J26: ⚠ 6.0wks > L=3 | K26: ⚠ Review

Sheet Overview
A1: Catering OR Project — Instance Overview
A3: Instance | B3: Design goal | C3: Key parameter lever
A4: Instance 1 (Base) | B4: Illustrative base case — all mechanisms active | C4: Balanced costs, 2 shelf lives, mild discount threshold
A5: Instance 2 (No Disc.) | B5: Discount never activated — shelf life too short | C5: Very short L_i = 1 vs high threshold m_i
A6: Instance 3 (Carry-over) | B6: Bulk buy + cross-week carryover dominates solution | C6: Low h_i, high m_i discount, long L_i = 3
A7: Instance 4 (Sensitivity) | B7: Sensitivity: vary waste/hold cost ratio & threshold | C7: w_i and h_i swept; m_i varied ±50%
A8: Instance 5 (Large) | B8: Scalability test — 6 ingredients, 6 dishes, 4 weeks | C8: Larger |I|=6, |D|=6, richer recipe matrix
A10: All instances share the same MILP formulation from the proposal. Parameters are chosen to stress-test specific model behaviours. Notation follows the proposal exactly (c_i, c̄_i, m_i, M_i, h_i, w_i, L_i).

Sheet Instance 1 (Base)
A1: Instance 1 (Base) — Base illustrative case
A2: Design goal: All model mechanisms active simultaneously
A3: 🔵 Blue-shaded cells = corrected values (see Diagnostic Report sheet for reasons)
A5: A. Weekly demand (servings per dish per week)
A6: Dish | B6: Week 1 | C6: Week 2 | D6: Week 3 | E6: Week 4
A7: D1 (Tomato-Egg) | B7: 80 | C7: 90 | D7: 70 | E7: 100
A8: D2 (Spinach) | B8: 60 | C8: 80 | D8: 90 | E8: 70
A9: D3 (Chicken) | B9: 50 | C9: 60 | D9: 80 | E9: 90
A11: B. Recipes (units of ingredient per serving)
A12: Dish \ Ingredient | B12: Chicken Leg | C12: Tomato | D12: Egg | E12: Spinach
A13: D1 (Tomato-Egg) | B13: 0 | C13: 1 | D13: 1 | E13: 0
A14: D2 (Spinach) | B14: 0 | C14: 0 | D14: 0 | E14: 2
A15: D3 (Chicken) | B15: 1 | C15: 0 | D15: 0 | E15: 0
A17: C. Ingredient parameters
A18: Ingredient | B18: Regular cost cᵢ | C18: Disc. cost c̄ᵢ | D18: Min qty mᵢ | E18: Shelf life Lᵢ (wks) | F18: Holding cost hᵢ | G18: Waste cost wᵢ | I18: Discount saving %
A19: Chicken Leg | B19: 5 | C19: 4.5 | D19: 100 | E19: 2 | F19: 0.18 | G19: 1 | I19: 10.0% | J19: h adjusted: breakeven now 2.8 < L=2 wks... marginal
A20: Tomato | B20: 1 | C20: 0.85 | D20: 90 | E20: 1 | F20: 0.05 | G20: 0.3 | I20: 15.0% | J20: m fixed: was 200 (> M_i=100)
A21: Egg | B21: 0.5 | C21: 0.44 | D21: 150 | E21: 2 | F21: 0.02 | G21: 0.1 | I21: 12.0% | J21: m fixed: was 300 (> M_i=170)
A22: Spinach | B22: 0.8 | C22: 0.74 | D22: 150 | E22: 1 | F22: 0.03 | G22: 0.2 | I22: 7.5%
A24: D. Instance notes & expected model behaviour
A25: Base case reproducing the proposal example with realistic magnitudes. • Demand is moderate and varied across weeks — discount thresholds are reachable for most ingredients. • Chicken Leg (L=2) allows 1-week carryover; Tomato & Spinach (L=1) must be bought fresh each week. • Expected: discount activated for Egg and Chicken Leg in high-demand weeks; no carryover for L=1 items. • Provides the reference total cost against which other instances are compared.

Sheet Instance 2 (No Discount)
A1: Instance 2 (No Discount) — Discount never activated
A2: Design goal: Short shelf + high threshold block all discounts
A4: A. Weekly demand (servings per dish per week)
A5: Dish | B5: Week 1 | C5: Week 2 | D5: Week 3 | E5: Week 4
A6: D1 (Tomato-Egg) | B6: 40 | C6: 35 | D6: 30 | E6: 40
A7: D2 (Spinach) | B7: 30 | C7: 25 | D7: 35 | E7: 30
A8: D3 (Chicken) | B8: 20 | C8: 25 | D8: 20 | E8: 25
A10: B. Recipes (units of ingredient per serving)
A11: Dish \ Ingredient | B11: Chicken Leg | C11: Tomato | D11: Egg | E11: Spinach
A12: D1 (Tomato-Egg) | B12: 0 | C12: 1 | D12: 1 | E12: 0
A13: D2 (Spinach) | B13: 0 | C13: 0 | D13: 0 | E13: 2
A14: D3 (Chicken) | B14: 1 | C14: 0 | D14: 0 | E14: 0
A16: C. Ingredient parameters
A17: Ingredient | B17: Regular cost cᵢ | C17: Disc. cost c̄ᵢ | D17: Min qty mᵢ | E17: Shelf life Lᵢ (wks) | F17: Holding cost hᵢ | G17: Waste cost wᵢ | I17: Discount saving %
A18: Chicken Leg | B18: 5 | C18: 4.5 | D18: 200 | E18: 1 | F18: 0.2 | G18: 2.5 | I18: 10.0%
A19: Tomato | B19: 1 | C19: 0.85 | D19: 400 | E19: 1 | F19: 0.05 | G19: 0.8 | I19: 15.0%
A20: Egg | B20: 0.5 | C20: 0.44 | D20: 600 | E20: 1 | F20: 0.02 | G20: 0.4 | I20: 12.0%
A21: Spinach | B21: 0.8 | C21: 0.74 | D21: 300 | E21: 1 | F21: 0.03 | G21: 0.7 | I21: 7.5%
A23: D. Instance notes & expected model behaviour
A24: Discount-blocked instance: shelf life = 1 week for ALL ingredients and thresholds are 2–3× total demand. • Total 4-week demand for Chicken Leg ≈ 90 units; discount threshold = 200 → never reachable in one week. • High waste cost (2–5× Instance 1) makes any over-purchasing extremely penalised. • Expected: u_i,t = 0 for all i and t (discount never activated); model buys exactly to demand each week. • Validates that the binary discount variable correctly stays off when activation is uneconomical.

Sheet Instance 3 (Carryover)
A1: Instance 3 (Carryover) — Bulk-buy + carryover dominates
A2: Design goal: Long shelf & low holding reward advance purchasing
A3: 🔵 Blue-shaded cells = corrected values (see Diagnostic Report sheet for reasons)
A5: A. Weekly demand (servings per dish per week)
A6: Dish | B6: Week 1 | C6: Week 2 | D6: Week 3 | E6: Week 4
A7: D1 (Tomato-Egg) | B7: 20 | C7: 120 | D7: 20 | E7: 120
A8: D2 (Spinach) | B8: 10 | C8: 80 | D8: 10 | E8: 80
A9: D3 (Chicken) | B9: 15 | C9: 90 | D9: 15 | E9: 90
A11: B. Recipes (units of ingredient per serving)
A12: Dish \ Ingredient | B12: Chicken Leg | C12: Tomato | D12: Egg | E12: Spinach
A13: D1 (Tomato-Egg) | B13: 0 | C13: 1 | D13: 1 | E13: 0
A14: D2 (Spinach) | B14: 0 | C14: 0 | D14: 0 | E14: 2
A15: D3 (Chicken) | B15: 1 | C15: 0 | D15: 0 | E15: 0
A17: C. Ingredient parameters
A18: Ingredient | B18: Regular cost cᵢ | C18: Disc. cost c̄ᵢ | D18: Min qty mᵢ | E18: Shelf life Lᵢ (wks) | F18: Holding cost hᵢ | G18: Waste cost wᵢ | I18: Discount saving %
A19: Chicken Leg | B19: 5 | C19: 3.5 | D19: 100 | E19: 3 | F19: 0.55 | G19: 0.5 | I19: 30.0% | J19: h raised: was 0.05 (breakeven=30wks >> L=3)
A20: Tomato | B20: 1 | C20: 0.7 | D20: 100 | E20: 2 | F20: 0.2 | G20: 0.15 | I20: 30.0% | J20: h raised: was 0.02 (breakeven=15wks >> L=2)
A21: Egg | B21: 0.5 | C21: 0.35 | D21: 150 | E21: 3 | F21: 0.1 | G21: 0.05 | I21: 30.0% | J21: h raised: was 0.01 (breakeven=15wks >> L=3)
A22: Spinach | B22: 0.8 | C22: 0.55 | D22: 80 | E22: 2 | F22: 0.18 | G22: 0.1 | I22: 31.2% | J22: h raised: was 0.02 (breakeven=12.5wks >> L=2)
A24: D. Instance notes & expected model behaviour
A25: Carryover-dominant instance: long shelf lives (L=2–3) and very low holding costs. • Demand is deliberately spiky (low–high–low–high) so buying ahead in week 1 for week 2 is cheaper. • Discount thresholds are modest (80–150 units) and savings are large (30–40%). • Expected: model bulk-purchases in week 1 (or 3) to cover week 2 (or 4) demand using carryover inventory. • Discount activated in nearly every week; waste near zero since shelf life accommodates the strategy. • Validates age-indexed inventory tracking and cross-period inventory balance constraints.

Sheet Instance 4 (Sensitivity)
A1: Instance 4 (Sensitivity) — Sensitivity analysis
A2: Design goal: Flat demand isolates cost-parameter effects
A3: 🔵 Blue-shaded cells = corrected values (see Diagnostic Report sheet for reasons)
A5: A. Weekly demand (servings per dish per week)
A6: Dish | B6: Week 1 | C6: Week 2 | D6: Week 3 | E6: Week 4
A7: D1 (Tomato-Egg) | B7: 70 | C7: 70 | D7: 70 | E7: 70
A8: D2 (Spinach) | B8: 50 | C8: 50 | D8: 50 | E8: 50
A9: D3 (Chicken) | B9: 60 | C9: 60 | D9: 60 | E9: 60
A11: B. Recipes (units of ingredient per serving)
A12: Dish \ Ingredient | B12: Chicken Leg | C12: Tomato | D12: Egg | E12: Spinach
A13: D1 (Tomato-Egg) | B13: 0 | C13: 1 | D13: 1 | E13: 0
A14: D2 (Spinach) | B14: 0 | C14: 0 | D14: 0 | E14: 2
A15: D3 (Chicken) | B15: 1 | C15: 0 | D15: 0 | E15: 0
A17: C. Ingredient parameters
A18: Ingredient | B18: Regular cost cᵢ | C18: Disc. cost c̄ᵢ | D18: Min qty mᵢ | E18: Shelf life Lᵢ (wks) | F18: Holding cost hᵢ | G18: Waste cost wᵢ | I18: Discount saving %
A19: Chicken Leg | B19: 5 | C19: 4.5 | D19: 100 | E19: 2 | F19: 0.2 | G19: 1 | I19: 10.0%
A20: Tomato | B20: 1 | C20: 0.85 | D20: 65 | E20: 1 | F20: 0.05 | G20: 0.3 | I20: 15.0% | J20: m fixed: was 200 (> M_i=70); sensitivity still meaningful
A21: Egg | B21: 0.5 | C21: 0.44 | D21: 130 | E21: 2 | F21: 0.02 | G21: 0.1 | I21: 12.0% | J21: m fixed: was 300 (> M_i=140)
A22: Spinach | B22: 0.8 | C22: 0.74 | D22: 95 | E22: 1 | F22: 0.03 | G22: 0.2 | I22: 7.5% | J22: m fixed: was 150 (> M_i=100)
A24: D. Instance notes & expected model behaviour
A25: Base parameters (same as Instance 1 structure) with FLAT demand (70/50/60 servings/week every week). Sensitivity experiments to run by re-solving the model with each scenario below: • Vary w_i (waste cost): ×0.5, ×1 (base), ×2, ×5 → observe at what w_i the model stops discounting. • Vary h_i (holding cost): ×0.5, ×1, ×2, ×5 → observe when carryover disappears. • Vary m_i (discount threshold): ×0.5, ×1, ×2 → find the tipping point where discount is no longer activated. • Flat demand ensures total cost differences are attributable solely to cost-parameter changes, not demand variation.
A27: E. Sensitivity scenarios (re-solve model for each row)
A28: Scenario | B28: Parameter | C28: Multiplier | D28: New value (Chicken Leg example) | E28: Expected effect
A29: S1 | B29: w_i (waste cost) | C29: ×0.5 | D29: 0.50 $/unit | E29: Less penalty → mild over-purchase tolerated
A30: S2 | B30: w_i (waste cost) | C30: ×1 (base) | D30: 1.00 $/unit | E30: Reference point
A31: S3 | B31: w_i (waste cost) | C31: ×2 | D31: 2.00 $/unit | E31: Discount use drops; buy closer to demand
A32: S4 | B32: w_i (waste cost) | C32: ×5 | D32: 5.00 $/unit | E32: Discount never activated; buy-to-demand
A33: S5 | B33: h_i (holding) | C33: ×0.5 | D33: 0.10 $/unit/wk | E33: More carryover; discount more often
A34: S6 | B34: h_i (holding) | C34: ×2 | D34: 0.40 $/unit/wk | E34: Less carryover; smaller batches
A35: S7 | B35: h_i (holding) | C35: ×5 | D35: 1.00 $/unit/wk | E35: No carryover; buy fresh weekly
A36: S8 | B36: m_i (threshold) | C36: ×0.5 | D36: 50 units | E36: Discount trivially activated every week
A37: S9 | B37: m_i (threshold) | C37: ×2 | D37: 200 units | E37: Discount rarely activated (demand ≈190/wk)

Sheet Instance 5 (Large)
A1: Instance 5 (Large) — Large-scale scalability test
A2: Design goal: |I|=6, |D|=6, richer recipe coupling
A4: A. Weekly demand (servings per dish per week)
A5: Dish | B5: Week 1 | C5: Week 2 | D5: Week 3 | E5: Week 4
A6: D1 (Salad) | B6: 80 | C6: 95 | D6: 70 | E6: 110
A7: D2 (Stir-fry) | B7: 70 | C7: 80 | D7: 90 | E7: 85
A8: D3 (Roast) | B8: 60 | C8: 75 | D8: 65 | E8: 80
A9: D4 (Soup) | B9: 55 | C9: 60 | D9: 70 | E9: 65
A10: D5 (Sandwich) | B10: 90 | C10: 85 | D10: 95 | E10: 100
A11: D6 (Bowl) | B11: 75 | C11: 80 | D11: 85 | E11: 90
A13: B. Recipes (units of ingredient per serving)
A14: Dish \ Ingredient | B14: Chicken | C14: Beef | D14: Tomato | E14: Spinach | F14: Egg | G14: Rice
A15: D1 (Salad) | B15: 0 | C15: 0 | D15: 2 | E15: 1 | F15: 1 | G15: 0
A16: D2 (Stir-fry) | B16: 1 | C16: 0 | D16: 0 | E16: 2 | F16: 0 | G16: 1
A17: D3 (Roast) | B17: 0 | C17: 1 | D17: 1 | E17: 0 | F17: 0 | G17: 0
A18: D4 (Soup) | B18: 1 | C18: 0 | D18: 1 | E18: 1 | F18: 0 | G18: 0
A19: D5 (Sandwich) | B19: 0 | C19: 1 | D19: 0 | E19: 0 | F19: 1 | G19: 0
A20: D6 (Bowl) | B20: 1 | C20: 0 | D20: 0 | E20: 0 | F20: 1 | G20: 2
A22: C. Ingredient parameters
A23: Ingredient | B23: Regular cost cᵢ | C23: Disc. cost c̄ᵢ | D23: Min qty mᵢ | E23: Shelf life Lᵢ (wks) | F23: Holding cost hᵢ | G23: Waste cost wᵢ | I23: Discount saving %
A24: Chicken | B24: 4.5 | C24: 3.85 | D24: 200 | E24: 2 | F24: 0.18 | G24: 1.2 | I24: 14.4%
A25: Beef | B25: 6 | C25: 5.1 | D25: 150 | E25: 2 | F25: 0.22 | G25: 1.8 | I25: 15.0%
A26: Tomato | B26: 1 | C26: 0.82 | D26: 300 | E26: 1 | F26: 0.04 | G26: 0.25 | I26: 18.0%
A27: Spinach | B27: 0.8 | C27: 0.66 | D27: 200 | E27: 1 | F27: 0.03 | G27: 0.18 | I27: 17.5%
A28: Egg | B28: 0.5 | C28: 0.42 | D28: 400 | E28: 2 | F28: 0.02 | G28: 0.08 | I28: 16.0%
A29: Rice | B29: 0.3 | C29: 0.24 | D29: 500 | E29: 3 | F29: 0.01 | G29: 0.05 | I29: 20.0%
A31: D. Instance notes & expected model behaviour
A32: Scalability instance: |I|=6 ingredients, |D|=6 dishes, T=4 weeks — roughly 3× the variables of Instance 1. • Multiple ingredients appear in 2–3 dishes, creating coupled demand (e.g. Chicken used in D2, D4, D6). • Rice has shelf life L=3, enabling 2-week advance purchasing; Tomato & Spinach remain L=1. • Tests solver performance and constraint scaling: more age-indexed variables (inv^(a)_{i,t}) and binary u_{i,t}. • Expected: discount activated for Rice and Egg (high-volume, low-threshold ingredients); Beef and Chicken bought strategically across weeks due to coupled dish demand. • Report solve time and # variables/constraints to demonstrate practical tractability.

Sheet Formula Generator
A1: Formula Generator | Z1: =MATCH($B$2,$Z$2:$Z$6,0)
A2: Instance | B2: Instance 1 (Base) | Z2: Instance 1 (Base)
Z3: Instance 2 (No Discount)
A4: Weekly dish demand | Z4: Instance 3 (Carryover)
A5: Dish | B5: Week 1 | C5: Week 2 | D5: Week 3 | E5: Week 4 | Z5: Instance 4 (Sensitivity)
A6: =IF(CHOOSE($Z$1,'Instance 1 (Base)'!A6,'Instance 2 (No Discount)'!A6,'Instance 3 (Carryover)'!A6,'Instance 4 (Sensitivity)'!A6,'Instance 5 (Large)'!A6)="","",CHOOSE($Z$1,'Instance 1 (Base)'!A6,'Instance 2 (No Discount)'!A6,'Instance 3 (Carryover)'!A6,'Instance 4 (Sensitivity)'!A6,'Instance 5 (Large)'!A6)) | B6: =IF($A6="","",CHOOSE($Z$1,'Instance 1 (Base)'!B6,'Instance 2 (No Discount)'!B6,'Instance 3 (Carryover)'!B6,'Instance 4 (Sensitivity)'!B6,'Instance 5 (Large)'!B6)) | C6: =IF($A6="","",CHOOSE($Z$1,'Instance 1 (Base)'!C6,'Instance 2 (No Discount)'!C6,'Instance 3 (Carryover)'!C6,'Instance 4 (Sensitivity)'!C6,'Instance 5 (Large)'!C6)) | D6: =IF($A6="","",CHOOSE($Z$1,'Instance 1 (Base)'!D6,'Instance 2 (No Discount)'!D6,'Instance 3 (Carryover)'!D6,'Instance 4 (Sensitivity)'!D6,'Instance 5 (Large)'!D6)) | E6: =IF($A6="","",CHOOSE($Z$1,'Instance 1 (Base)'!E6,'Instance 2 (No Discount)'!E6,'Instance 3 (Carryover)'!E6,'Instance 4 (Sensitivity)'!E6,'Instance 5 (Large)'!E6)) | Z6: Instance 5 (Large)
A7: =IF(CHOOSE($Z$1,'Instance 1 (Base)'!A7,'Instance 2 (No Discount)'!A7,'Instance 3 (Carryover)'!A7,'Instance 4 (Sensitivity)'!A7,'Instance 5 (Large)'!A7)="","",CHOOSE($Z$1,'Instance 1 (Base)'!A7,'Instance 2 (No Discount)'!A7,'Instance 3 (Carryover)'!A7,'Instance 4 (Sensitivity)'!A7,'Instance 5 (Large)'!A7)) | B7: =IF($A7="","",CHOOSE($Z$1,'Instance 1 (Base)'!B7,'Instance 2 (No Discount)'!B7,'Instance 3 (Carryover)'!B7,'Instance 4 (Sensitivity)'!B7,'Instance 5 (Large)'!B7)) | C7: =IF($A7="","",CHOOSE($Z$1,'Instance 1 (Base)'!C7,'Instance 2 (No Discount)'!C7,'Instance 3 (Carryover)'!C7,'Instance 4 (Sensitivity)'!C7,'Instance 5 (Large)'!C7)) | D7: =IF($A7="","",CHOOSE($Z$1,'Instance 1 (Base)'!D7,'Instance 2 (No Discount)'!D7,'Instance 3 (Carryover)'!D7,'Instance 4 (Sensitivity)'!D7,'Instance 5 (Large)'!D7)) | E7: =IF($A7="","",CHOOSE($Z$1,'Instance 1 (Base)'!E7,'Instance 2 (No Discount)'!E7,'Instance 3 (Carryover)'!E7,'Instance 4 (Sensitivity)'!E7,'Instance 5 (Large)'!E7))
A8: =IF(CHOOSE($Z$1,'Instance 1 (Base)'!A8,'Instance 2 (No Discount)'!A8,'Instance 3 (Carryover)'!A8,'Instance 4 (Sensitivity)'!A8,'Instance 5 (Large)'!A8)="","",CHOOSE($Z$1,'Instance 1 (Base)'!A8,'Instance 2 (No Discount)'!A8,'Instance 3 (Carryover)'!A8,'Instance 4 (Sensitivity)'!A8,'Instance 5 (Large)'!A8)) | B8: =IF($A8="","",CHOOSE($Z$1,'Instance 1 (Base)'!B8,'Instance 2 (No Discount)'!B8,'Instance 3 (Carryover)'!B8,'Instance 4 (Sensitivity)'!B8,'Instance 5 (Large)'!B8)) | C8: =IF($A8="","",CHOOSE($Z$1,'Instance 1 (Base)'!C8,'Instance 2 (No Discount)'!C8,'Instance 3 (Carryover)'!C8,'Instance 4 (Sensitivity)'!C8,'Instance 5 (Large)'!C8)) | D8: =IF($A8="","",CHOOSE($Z$1,'Instance 1 (Base)'!D8,'Instance 2 (No Discount)'!D8,'Instance 3 (Carryover)'!D8,'Instance 4 (Sensitivity)'!D8,'Instance 5 (Large)'!D8)) | E8: =IF($A8="","",CHOOSE($Z$1,'Instance 1 (Base)'!E8,'Instance 2 (No Discount)'!E8,'Instance 3 (Carryover)'!E8,'Instance 4 (Sensitivity)'!E8,'Instance 5 (Large)'!E8))
A9: =IF(CHOOSE($Z$1,"","","","",'Instance 5 (Large)'!A9)="","",CHOOSE($Z$1,"","","","",'Instance 5 (Large)'!A9)) | B9: =IF($A9="","",CHOOSE($Z$1,"","","","",'Instance 5 (Large)'!B9)) | C9: =IF($A9="","",CHOOSE($Z$1,"","","","",'Instance 5 (Large)'!C9)) | D9: =IF($A9="","",CHOOSE($Z$1,"","","","",'Instance 5 (Large)'!D9)) | E9: =IF($A9="","",CHOOSE($Z$1,"","","","",'Instance 5 (Large)'!E9))
A10: =IF(CHOOSE($Z$1,"","","","",'Instance 5 (Large)'!A10)="","",CHOOSE($Z$1,"","","","",'Instance 5 (Large)'!A10)) | B10: =IF($A10="","",CHOOSE($Z$1,"","","","",'Instance 5 (Large)'!B10)) | C10: =IF($A10="","",CHOOSE($Z$1,"","","","",'Instance 5 (Large)'!C10)) | D10: =IF($A10="","",CHOOSE($Z$1,"","","","",'Instance 5 (Large)'!D10)) | E10: =IF($A10="","",CHOOSE($Z$1,"","","","",'Instance 5 (Large)'!E10))
A11: =IF(CHOOSE($Z$1,"","","","",'Instance 5 (Large)'!A11)="","",CHOOSE($Z$1,"","","","",'Instance 5 (Large)'!A11)) | B11: =IF($A11="","",CHOOSE($Z$1,"","","","",'Instance 5 (Large)'!B11)) | C11: =IF($A11="","",CHOOSE($Z$1,"","","","",'Instance 5 (Large)'!C11)) | D11: =IF($A11="","",CHOOSE($Z$1,"","","","",'Instance 5 (Large)'!D11)) | E11: =IF($A11="","",CHOOSE($Z$1,"","","","",'Instance 5 (Large)'!E11))
A13: Recipe matrix
A14: ="Dish \ Ingredient" | B14: =IF(CHOOSE($Z$1,'Instance 1 (Base)'!B11,'Instance 2 (No Discount)'!B11,'Instance 3 (Carryover)'!B11,'Instance 4 (Sensitivity)'!B11,'Instance 5 (Large)'!B14)="","",CHOOSE($Z$1,'Instance 1 (Base)'!B11,'Instance 2 (No Discount)'!B11,'Instance 3 (Carryover)'!B11,'Instance 4 (Sensitivity)'!B11,'Instance 5 (Large)'!B14)) | C14: =IF(CHOOSE($Z$1,'Instance 1 (Base)'!C11,'Instance 2 (No Discount)'!C11,'Instance 3 (Carryover)'!C11,'Instance 4 (Sensitivity)'!C11,'Instance 5 (Large)'!C14)="","",CHOOSE($Z$1,'Instance 1 (Base)'!C11,'Instance 2 (No Discount)'!C11,'Instance 3 (Carryover)'!C11,'Instance 4 (Sensitivity)'!C11,'Instance 5 (Large)'!C14)) | D14: =IF(CHOOSE($Z$1,'Instance 1 (Base)'!D11,'Instance 2 (No Discount)'!D11,'Instance 3 (Carryover)'!D11,'Instance 4 (Sensitivity)'!D11,'Instance 5 (Large)'!D14)="","",CHOOSE($Z$1,'Instance 1 (Base)'!D11,'Instance 2 (No Discount)'!D11,'Instance 3 (Carryover)'!D11,'Instance 4 (Sensitivity)'!D11,'Instance 5 (Large)'!D14)) | E14: =IF(CHOOSE($Z$1,'Instance 1 (Base)'!E11,'Instance 2 (No Discount)'!E11,'Instance 3 (Carryover)'!E11,'Instance 4 (Sensitivity)'!E11,'Instance 5 (Large)'!E14)="","",CHOOSE($Z$1,'Instance 1 (Base)'!E11,'Instance 2 (No Discount)'!E11,'Instance 3 (Carryover)'!E11,'Instance 4 (Sensitivity)'!E11,'Instance 5 (Large)'!E14)) | F14: =IF(CHOOSE($Z$1,'Instance 1 (Base)'!F11,'Instance 2 (No Discount)'!F11,'Instance 3 (Carryover)'!F11,'Instance 4 (Sensitivity)'!F11,'Instance 5 (Large)'!F14)="","",CHOOSE($Z$1,'Instance 1 (Base)'!F11,'Instance 2 (No Discount)'!F11,'Instance 3 (Carryover)'!F11,'Instance 4 (Sensitivity)'!F11,'Instance 5 (Large)'!F14)) | G14: =IF(CHOOSE($Z$1,'Instance 1 (Base)'!G11,'Instance 2 (No Discount)'!G11,'Instance 3 (Carryover)'!G11,'Instance 4 (Sensitivity)'!G11,'Instance 5 (Large)'!G14)="","",CHOOSE($Z$1,'Instance 1 (Base)'!G11,'Instance 2 (No Discount)'!G11,'Instance 3 (Carryover)'!G11,'Instance 4 (Sensitivity)'!G11,'Instance 5 (Large)'!G14))
A15: =IF(CHOOSE($Z$1,'Instance 1 (Base)'!A12,'Instance 2 (No Discount)'!A12,'Instance 3 (Carryover)'!A12,'Instance 4 (Sensitivity)'!A12,'Instance 5 (Large)'!A15)="","",CHOOSE($Z$1,'Instance 1 (Base)'!A12,'Instance 2 (No Discount)'!A12,'Instance 3 (Carryover)'!A12,'Instance 4 (Sensitivity)'!A12,'Instance 5 (Large)'!A15)) | B15: =IF(OR($A15="",B$14=""),"",CHOOSE($Z$1,'Instance 1 (Base)'!B12,'Instance 2 (No Discount)'!B12,'Instance 3 (Carryover)'!B12,'Instance 4 (Sensitivity)'!B12,'Instance 5 (Large)'!B15)) | C15: =IF(OR($A15="",C$14=""),"",CHOOSE($Z$1,'Instance 1 (Base)'!C12,'Instance 2 (No Discount)'!C12,'Instance 3 (Carryover)'!C12,'Instance 4 (Sensitivity)'!C12,'Instance 5 (Large)'!C15)) | D15: =IF(OR($A15="",D$14=""),"",CHOOSE($Z$1,'Instance 1 (Base)'!D12,'Instance 2 (No Discount)'!D12,'Instance 3 (Carryover)'!D12,'Instance 4 (Sensitivity)'!D12,'Instance 5 (Large)'!D15)) | E15: =IF(OR($A15="",E$14=""),"",CHOOSE($Z$1,'Instance 1 (Base)'!E12,'Instance 2 (No Discount)'!E12,'Instance 3 (Carryover)'!E12,'Instance 4 (Sensitivity)'!E12,'Instance 5 (Large)'!E15)) | F15: =IF(OR($A15="",F$14=""),"",CHOOSE($Z$1,'Instance 1 (Base)'!F12,'Instance 2 (No Discount)'!F12,'Instance 3 (Carryover)'!F12,'Instance 4 (Sensitivity)'!F12,'Instance 5 (Large)'!F15)) | G15: =IF(OR($A15="",G$14=""),"",CHOOSE($Z$1,'Instance 1 (Base)'!G12,'Instance 2 (No Discount)'!G12,'Instance 3 (Carryover)'!G12,'Instance 4 (Sensitivity)'!G12,'Instance 5 (Large)'!G15))
A16: =IF(CHOOSE($Z$1,'Instance 1 (Base)'!A13,'Instance 2 (No Discount)'!A13,'Instance 3 (Carryover)'!A13,'Instance 4 (Sensitivity)'!A13,'Instance 5 (Large)'!A16)="","",CHOOSE($Z$1,'Instance 1 (Base)'!A13,'Instance 2 (No Discount)'!A13,'Instance 3 (Carryover)'!A13,'Instance 4 (Sensitivity)'!A13,'Instance 5 (Large)'!A16)) | B16: =IF(OR($A16="",B$14=""),"",CHOOSE($Z$1,'Instance 1 (Base)'!B13,'Instance 2 (No Discount)'!B13,'Instance 3 (Carryover)'!B13,'Instance 4 (Sensitivity)'!B13,'Instance 5 (Large)'!B16)) | C16: =IF(OR($A16="",C$14=""),"",CHOOSE($Z$1,'Instance 1 (Base)'!C13,'Instance 2 (No Discount)'!C13,'Instance 3 (Carryover)'!C13,'Instance 4 (Sensitivity)'!C13,'Instance 5 (Large)'!C16)) | D16: =IF(OR($A16="",D$14=""),"",CHOOSE($Z$1,'Instance 1 (Base)'!D13,'Instance 2 (No Discount)'!D13,'Instance 3 (Carryover)'!D13,'Instance 4 (Sensitivity)'!D13,'Instance 5 (Large)'!D16)) | E16: =IF(OR($A16="",E$14=""),"",CHOOSE($Z$1,'Instance 1 (Base)'!E13,'Instance 2 (No Discount)'!E13,'Instance 3 (Carryover)'!E13,'Instance 4 (Sensitivity)'!E13,'Instance 5 (Large)'!E16)) | F16: =IF(OR($A16="",F$14=""),"",CHOOSE($Z$1,'Instance 1 (Base)'!F13,'Instance 2 (No Discount)'!F13,'Instance 3 (Carryover)'!F13,'Instance 4 (Sensitivity)'!F13,'Instance 5 (Large)'!F16)) | G16: =IF(OR($A16="",G$14=""),"",CHOOSE($Z$1,'Instance 1 (Base)'!G13,'Instance 2 (No Discount)'!G13,'Instance 3 (Carryover)'!G13,'Instance 4 (Sensitivity)'!G13,'Instance 5 (Large)'!G16))
A17: =IF(CHOOSE($Z$1,'Instance 1 (Base)'!A14,'Instance 2 (No Discount)'!A14,'Instance 3 (Carryover)'!A14,'Instance 4 (Sensitivity)'!A14,'Instance 5 (Large)'!A17)="","",CHOOSE($Z$1,'Instance 1 (Base)'!A14,'Instance 2 (No Discount)'!A14,'Instance 3 (Carryover)'!A14,'Instance 4 (Sensitivity)'!A14,'Instance 5 (Large)'!A17)) | B17: =IF(OR($A17="",B$14=""),"",CHOOSE($Z$1,'Instance 1 (Base)'!B14,'Instance 2 (No Discount)'!B14,'Instance 3 (Carryover)'!B14,'Instance 4 (Sensitivity)'!B14,'Instance 5 (Large)'!B17)) | C17: =IF(OR($A17="",C$14=""),"",CHOOSE($Z$1,'Instance 1 (Base)'!C14,'Instance 2 (No Discount)'!C14,'Instance 3 (Carryover)'!C14,'Instance 4 (Sensitivity)'!C14,'Instance 5 (Large)'!C17)) | D17: =IF(OR($A17="",D$14=""),"",CHOOSE($Z$1,'Instance 1 (Base)'!D14,'Instance 2 (No Discount)'!D14,'Instance 3 (Carryover)'!D14,'Instance 4 (Sensitivity)'!D14,'Instance 5 (Large)'!D17)) | E17: =IF(OR($A17="",E$14=""),"",CHOOSE($Z$1,'Instance 1 (Base)'!E14,'Instance 2 (No Discount)'!E14,'Instance 3 (Carryover)'!E14,'Instance 4 (Sensitivity)'!E14,'Instance 5 (Large)'!E17)) | F17: =IF(OR($A17="",F$14=""),"",CHOOSE($Z$1,'Instance 1 (Base)'!F14,'Instance 2 (No Discount)'!F14,'Instance 3 (Carryover)'!F14,'Instance 4 (Sensitivity)'!F14,'Instance 5 (Large)'!F17)) | G17: =IF(OR($A17="",G$14=""),"",CHOOSE($Z$1,'Instance 1 (Base)'!G14,'Instance 2 (No Discount)'!G14,'Instance 3 (Carryover)'!G14,'Instance 4 (Sensitivity)'!G14,'Instance 5 (Large)'!G17))
A18: =IF(CHOOSE($Z$1,"","","","",'Instance 5 (Large)'!A18)="","",CHOOSE($Z$1,"","","","",'Instance 5 (Large)'!A18)) | B18: =IF(OR($A18="",B$14=""),"",CHOOSE($Z$1,"","","","",'Instance 5 (Large)'!B18)) | C18: =IF(OR($A18="",C$14=""),"",CHOOSE($Z$1,"","","","",'Instance 5 (Large)'!C18)) | D18: =IF(OR($A18="",D$14=""),"",CHOOSE($Z$1,"","","","",'Instance 5 (Large)'!D18)) | E18: =IF(OR($A18="",E$14=""),"",CHOOSE($Z$1,"","","","",'Instance 5 (Large)'!E18)) | F18: =IF(OR($A18="",F$14=""),"",CHOOSE($Z$1,"","","","",'Instance 5 (Large)'!F18)) | G18: =IF(OR($A18="",G$14=""),"",CHOOSE($Z$1,"","","","",'Instance 5 (Large)'!G18))
A19: =IF(CHOOSE($Z$1,"","","","",'Instance 5 (Large)'!A19)="","",CHOOSE($Z$1,"","","","",'Instance 5 (Large)'!A19)) | B19: =IF(OR($A19="",B$14=""),"",CHOOSE($Z$1,"","","","",'Instance 5 (Large)'!B19)) | C19: =IF(OR($A19="",C$14=""),"",CHOOSE($Z$1,"","","","",'Instance 5 (Large)'!C19)) | D19: =IF(OR($A19="",D$14=""),"",CHOOSE($Z$1,"","","","",'Instance 5 (Large)'!D19)) | E19: =IF(OR($A19="",E$14=""),"",CHOOSE($Z$1,"","","","",'Instance 5 (Large)'!E19)) | F19: =IF(OR($A19="",F$14=""),"",CHOOSE($Z$1,"","","","",'Instance 5 (Large)'!F19)) | G19: =IF(OR($A19="",G$14=""),"",CHOOSE($Z$1,"","","","",'Instance 5 (Large)'!G19))
A20: =IF(CHOOSE($Z$1,"","","","",'Instance 5 (Large)'!A20)="","",CHOOSE($Z$1,"","","","",'Instance 5 (Large)'!A20)) | B20: =IF(OR($A20="",B$14=""),"",CHOOSE($Z$1,"","","","",'Instance 5 (Large)'!B20)) | C20: =IF(OR($A20="",C$14=""),"",CHOOSE($Z$1,"","","","",'Instance 5 (Large)'!C20)) | D20: =IF(OR($A20="",D$14=""),"",CHOOSE($Z$1,"","","","",'Instance 5 (Large)'!D20)) | E20: =IF(OR($A20="",E$14=""),"",CHOOSE($Z$1,"","","","",'Instance 5 (Large)'!E20)) | F20: =IF(OR($A20="",F$14=""),"",CHOOSE($Z$1,"","","","",'Instance 5 (Large)'!F20)) | G20: =IF(OR($A20="",G$14=""),"",CHOOSE($Z$1,"","","","",'Instance 5 (Large)'!G20))
A22: Ingredient parameters
A23: Ingredient | B23: Regular cost | C23: Discount cost | D23: Min qty | E23: Shelf life | F23: Holding cost | G23: Waste cost | H23: Discount saving % | I23: w / h
A24: =IF(CHOOSE($Z$1,'Instance 1 (Base)'!A18,'Instance 2 (No Discount)'!A18,'Instance 3 (Carryover)'!A18,'Instance 4 (Sensitivity)'!A18,'Instance 5 (Large)'!A24)="","",CHOOSE($Z$1,'Instance 1 (Base)'!A18,'Instance 2 (No Discount)'!A18,'Instance 3 (Carryover)'!A18,'Instance 4 (Sensitivity)'!A18,'Instance 5 (Large)'!A24)) | B24: =IF($A24="","",CHOOSE($Z$1,'Instance 1 (Base)'!B18,'Instance 2 (No Discount)'!B18,'Instance 3 (Carryover)'!B18,'Instance 4 (Sensitivity)'!B18,'Instance 5 (Large)'!B24)) | C24: =IF($A24="","",CHOOSE($Z$1,'Instance 1 (Base)'!C18,'Instance 2 (No Discount)'!C18,'Instance 3 (Carryover)'!C18,'Instance 4 (Sensitivity)'!C18,'Instance 5 (Large)'!C24)) | D24: =IF($A24="","",CHOOSE($Z$1,'Instance 1 (Base)'!D18,'Instance 2 (No Discount)'!D18,'Instance 3 (Carryover)'!D18,'Instance 4 (Sensitivity)'!D18,'Instance 5 (Large)'!D24)) | E24: =IF($A24="","",CHOOSE($Z$1,'Instance 1 (Base)'!E18,'Instance 2 (No Discount)'!E18,'Instance 3 (Carryover)'!E18,'Instance 4 (Sensitivity)'!E18,'Instance 5 (Large)'!E24)) | F24: =IF($A24="","",CHOOSE($Z$1,'Instance 1 (Base)'!F18,'Instance 2 (No Discount)'!F18,'Instance 3 (Carryover)'!F18,'Instance 4 (Sensitivity)'!F18,'Instance 5 (Large)'!F24)) | G24: =IF($A24="","",CHOOSE($Z$1,'Instance 1 (Base)'!G18,'Instance 2 (No Discount)'!G18,'Instance 3 (Carryover)'!G18,'Instance 4 (Sensitivity)'!G18,'Instance 5 (Large)'!G24)) | H24: =IF($A24="","",IF(B24=0,"",(B24-C24)/B24)) | I24: =IF($A24="","",IF(F24=0,"",G24/F24))
A25: =IF(CHOOSE($Z$1,'Instance 1 (Base)'!A19,'Instance 2 (No Discount)'!A19,'Instance 3 (Carryover)'!A19,'Instance 4 (Sensitivity)'!A19,'Instance 5 (Large)'!A25)="","",CHOOSE($Z$1,'Instance 1 (Base)'!A19,'Instance 2 (No Discount)'!A19,'Instance 3 (Carryover)'!A19,'Instance 4 (Sensitivity)'!A19,'Instance 5 (Large)'!A25)) | B25: =IF($A25="","",CHOOSE($Z$1,'Instance 1 (Base)'!B19,'Instance 2 (No Discount)'!B19,'Instance 3 (Carryover)'!B19,'Instance 4 (Sensitivity)'!B19,'Instance 5 (Large)'!B25)) | C25: =IF($A25="","",CHOOSE($Z$1,'Instance 1 (Base)'!C19,'Instance 2 (No Discount)'!C19,'Instance 3 (Carryover)'!C19,'Instance 4 (Sensitivity)'!C19,'Instance 5 (Large)'!C25)) | D25: =IF($A25="","",CHOOSE($Z$1,'Instance 1 (Base)'!D19,'Instance 2 (No Discount)'!D19,'Instance 3 (Carryover)'!D19,'Instance 4 (Sensitivity)'!D19,'Instance 5 (Large)'!D25)) | E25: =IF($A25="","",CHOOSE($Z$1,'Instance 1 (Base)'!E19,'Instance 2 (No Discount)'!E19,'Instance 3 (Carryover)'!E19,'Instance 4 (Sensitivity)'!E19,'Instance 5 (Large)'!E25)) | F25: =IF($A25="","",CHOOSE($Z$1,'Instance 1 (Base)'!F19,'Instance 2 (No Discount)'!F19,'Instance 3 (Carryover)'!F19,'Instance 4 (Sensitivity)'!F19,'Instance 5 (Large)'!F25)) | G25: =IF($A25="","",CHOOSE($Z$1,'Instance 1 (Base)'!G19,'Instance 2 (No Discount)'!G19,'Instance 3 (Carryover)'!G19,'Instance 4 (Sensitivity)'!G19,'Instance 5 (Large)'!G25)) | H25: =IF($A25="","",IF(B25=0,"",(B25-C25)/B25)) | I25: =IF($A25="","",IF(F25=0,"",G25/F25))
A26: =IF(CHOOSE($Z$1,'Instance 1 (Base)'!A20,'Instance 2 (No Discount)'!A20,'Instance 3 (Carryover)'!A20,'Instance 4 (Sensitivity)'!A20,'Instance 5 (Large)'!A26)="","",CHOOSE($Z$1,'Instance 1 (Base)'!A20,'Instance 2 (No Discount)'!A20,'Instance 3 (Carryover)'!A20,'Instance 4 (Sensitivity)'!A20,'Instance 5 (Large)'!A26)) | B26: =IF($A26="","",CHOOSE($Z$1,'Instance 1 (Base)'!B20,'Instance 2 (No Discount)'!B20,'Instance 3 (Carryover)'!B20,'Instance 4 (Sensitivity)'!B20,'Instance 5 (Large)'!B26)) | C26: =IF($A26="","",CHOOSE($Z$1,'Instance 1 (Base)'!C20,'Instance 2 (No Discount)'!C20,'Instance 3 (Carryover)'!C20,'Instance 4 (Sensitivity)'!C20,'Instance 5 (Large)'!C26)) | D26: =IF($A26="","",CHOOSE($Z$1,'Instance 1 (Base)'!D20,'Instance 2 (No Discount)'!D20,'Instance 3 (Carryover)'!D20,'Instance 4 (Sensitivity)'!D20,'Instance 5 (Large)'!D26)) | E26: =IF($A26="","",CHOOSE($Z$1,'Instance 1 (Base)'!E20,'Instance 2 (No Discount)'!E20,'Instance 3 (Carryover)'!E20,'Instance 4 (Sensitivity)'!E20,'Instance 5 (Large)'!E26)) | F26: =IF($A26="","",CHOOSE($Z$1,'Instance 1 (Base)'!F20,'Instance 2 (No Discount)'!F20,'Instance 3 (Carryover)'!F20,'Instance 4 (Sensitivity)'!F20,'Instance 5 (Large)'!F26)) | G26: =IF($A26="","",CHOOSE($Z$1,'Instance 1 (Base)'!G20,'Instance 2 (No Discount)'!G20,'Instance 3 (Carryover)'!G20,'Instance 4 (Sensitivity)'!G20,'Instance 5 (Large)'!G26)) | H26: =IF($A26="","",IF(B26=0,"",(B26-C26)/B26)) | I26: =IF($A26="","",IF(F26=0,"",G26/F26))
A27: =IF(CHOOSE($Z$1,'Instance 1 (Base)'!A21,'Instance 2 (No Discount)'!A21,'Instance 3 (Carryover)'!A21,'Instance 4 (Sensitivity)'!A21,'Instance 5 (Large)'!A27)="","",CHOOSE($Z$1,'Instance 1 (Base)'!A21,'Instance 2 (No Discount)'!A21,'Instance 3 (Carryover)'!A21,'Instance 4 (Sensitivity)'!A21,'Instance 5 (Large)'!A27)) | B27: =IF($A27="","",CHOOSE($Z$1,'Instance 1 (Base)'!B21,'Instance 2 (No Discount)'!B21,'Instance 3 (Carryover)'!B21,'Instance 4 (Sensitivity)'!B21,'Instance 5 (Large)'!B27)) | C27: =IF($A27="","",CHOOSE($Z$1,'Instance 1 (Base)'!C21,'Instance 2 (No Discount)'!C21,'Instance 3 (Carryover)'!C21,'Instance 4 (Sensitivity)'!C21,'Instance 5 (Large)'!C27)) | D27: =IF($A27="","",CHOOSE($Z$1,'Instance 1 (Base)'!D21,'Instance 2 (No Discount)'!D21,'Instance 3 (Carryover)'!D21,'Instance 4 (Sensitivity)'!D21,'Instance 5 (Large)'!D27)) | E27: =IF($A27="","",CHOOSE($Z$1,'Instance 1 (Base)'!E21,'Instance 2 (No Discount)'!E21,'Instance 3 (Carryover)'!E21,'Instance 4 (Sensitivity)'!E21,'Instance 5 (Large)'!E27)) | F27: =IF($A27="","",CHOOSE($Z$1,'Instance 1 (Base)'!F21,'Instance 2 (No Discount)'!F21,'Instance 3 (Carryover)'!F21,'Instance 4 (Sensitivity)'!F21,'Instance 5 (Large)'!F27)) | G27: =IF($A27="","",CHOOSE($Z$1,'Instance 1 (Base)'!G21,'Instance 2 (No Discount)'!G21,'Instance 3 (Carryover)'!G21,'Instance 4 (Sensitivity)'!G21,'Instance 5 (Large)'!G27)) | H27: =IF($A27="","",IF(B27=0,"",(B27-C27)/B27)) | I27: =IF($A27="","",IF(F27=0,"",G27/F27))
A28: =IF(CHOOSE($Z$1,"","","","",'Instance 5 (Large)'!A28)="","",CHOOSE($Z$1,"","","","",'Instance 5 (Large)'!A28)) | B28: =IF($A28="","",CHOOSE($Z$1,"","","","",'Instance 5 (Large)'!B28)) | C28: =IF($A28="","",CHOOSE($Z$1,"","","","",'Instance 5 (Large)'!C28)) | D28: =IF($A28="","",CHOOSE($Z$1,"","","","",'Instance 5 (Large)'!D28)) | E28: =IF($A28="","",CHOOSE($Z$1,"","","","",'Instance 5 (Large)'!E28)) | F28: =IF($A28="","",CHOOSE($Z$1,"","","","",'Instance 5 (Large)'!F28)) | G28: =IF($A28="","",CHOOSE($Z$1,"","","","",'Instance 5 (Large)'!G28)) | H28: =IF($A28="","",IF(B28=0,"",(B28-C28)/B28)) | I28: =IF($A28="","",IF(F28=0,"",G28/F28))
A29: =IF(CHOOSE($Z$1,"","","","",'Instance 5 (Large)'!A29)="","",CHOOSE($Z$1,"","","","",'Instance 5 (Large)'!A29)) | B29: =IF($A29="","",CHOOSE($Z$1,"","","","",'Instance 5 (Large)'!B29)) | C29: =IF($A29="","",CHOOSE($Z$1,"","","","",'Instance 5 (Large)'!C29)) | D29: =IF($A29="","",CHOOSE($Z$1,"","","","",'Instance 5 (Large)'!D29)) | E29: =IF($A29="","",CHOOSE($Z$1,"","","","",'Instance 5 (Large)'!E29)) | F29: =IF($A29="","",CHOOSE($Z$1,"","","","",'Instance 5 (Large)'!F29)) | G29: =IF($A29="","",CHOOSE($Z$1,"","","","",'Instance 5 (Large)'!G29)) | H29: =IF($A29="","",IF(B29=0,"",(B29-C29)/B29)) | I29: =IF($A29="","",IF(F29=0,"",G29/F29))
A31: Ingredient demand
A32: Ingredient | B32: Week 1 | C32: Week 2 | D32: Week 3 | E32: Week 4
A33: {=IF(INDEX($A$24:$A$29,1)="","",INDEX($A$24:$A$29,1))} | B33: =IF($A33="","",SUMPRODUCT(B$6:B$11,B$15:B$20)) | C33: =IF($A33="","",SUMPRODUCT(C$6:C$11,B$15:B$20)) | D33: =IF($A33="","",SUMPRODUCT(D$6:D$11,B$15:B$20)) | E33: =IF($A33="","",SUMPRODUCT(E$6:E$11,B$15:B$20))
A34: {=IF(INDEX($A$24:$A$29,2)="","",INDEX($A$24:$A$29,2))} | B34: =IF($A34="","",SUMPRODUCT(B$6:B$11,C$15:C$20)) | C34: =IF($A34="","",SUMPRODUCT(C$6:C$11,C$15:C$20)) | D34: =IF($A34="","",SUMPRODUCT(D$6:D$11,C$15:C$20)) | E34: =IF($A34="","",SUMPRODUCT(E$6:E$11,C$15:C$20))
A35: {=IF(INDEX($A$24:$A$29,3)="","",INDEX($A$24:$A$29,3))} | B35: =IF($A35="","",SUMPRODUCT(B$6:B$11,D$15:D$20)) | C35: =IF($A35="","",SUMPRODUCT(C$6:C$11,D$15:D$20)) | D35: =IF($A35="","",SUMPRODUCT(D$6:D$11,D$15:D$20)) | E35: =IF($A35="","",SUMPRODUCT(E$6:E$11,D$15:D$20))
A36: {=IF(INDEX($A$24:$A$29,4)="","",INDEX($A$24:$A$29,4))} | B36: =IF($A36="","",SUMPRODUCT(B$6:B$11,E$15:E$20)) | C36: =IF($A36="","",SUMPRODUCT(C$6:C$11,E$15:E$20)) | D36: =IF($A36="","",SUMPRODUCT(D$6:D$11,E$15:E$20)) | E36: =IF($A36="","",SUMPRODUCT(E$6:E$11,E$15:E$20))
A37: {=IF(INDEX($A$24:$A$29,5)="","",INDEX($A$24:$A$29,5))} | B37: =IF($A37="","",SUMPRODUCT(B$6:B$11,F$15:F$20)) | C37: =IF($A37="","",SUMPRODUCT(C$6:C$11,F$15:F$20)) | D37: =IF($A37="","",SUMPRODUCT(D$6:D$11,F$15:F$20)) | E37: =IF($A37="","",SUMPRODUCT(E$6:E$11,F$15:F$20))
A38: {=IF(INDEX($A$24:$A$29,6)="","",INDEX($A$24:$A$29,6))} | B38: =IF($A38="","",SUMPRODUCT(B$6:B$11,G$15:G$20)) | C38: =IF($A38="","",SUMPRODUCT(C$6:C$11,G$15:G$20)) | D38: =IF($A38="","",SUMPRODUCT(D$6:D$11,G$15:G$20)) | E38: =IF($A38="","",SUMPRODUCT(E$6:E$11,G$15:G$20))
A40: Formula summary
A41: Ingredient | B41: Total demand | C41: Max weekly demand | D41: Min qty | E41: Shelf life | F41: Recommended M | G41: Reachable | H41: Discount saving % | I41: Holding cost | J41: Waste cost | K41: Breakeven (wks) | L41: Breakeven ≤ L?
A42: =IF(A33="","",A33) | B42: =IF($A42="","",SUM(B33:E33)) | C42: =IF($A42="","",MAX(B33:E33)) | D42: =IF($A42="","",D24) | E42: =IF($A42="","",E24) | F42: =IF($A42="","",MAX(SUM(B33:INDEX($B33:$E33,1,MIN($E42,4))),SUM(C33:INDEX($B33:$E33,1,MIN($E42+1,4))),SUM(D33:INDEX($B33:$E33,1,MIN($E42+2,4))),E33)) | G42: =IF($A42="","",IF(D42<=F42,"Yes","No")) | H42: =IF($A42="","",H24) | I42: =IF($A42="","",F24) | J42: =IF($A42="","",G24) | K42: 2.8 | L42: ⚠ 2.8>2
A43: =IF(A34="","",A34) | B43: =IF($A43="","",SUM(B34:E34)) | C43: =IF($A43="","",MAX(B34:E34)) | D43: =IF($A43="","",D25) | E43: =IF($A43="","",E25) | F43: =IF($A43="","",MAX(SUM(B33:INDEX($B34:$E34,1,MIN($E43,4))),SUM(C33:INDEX($B34:$E34,1,MIN($E43+1,4))),SUM(D33:INDEX($B34:$E34,1,MIN($E43+2,4))),E34)) | G43: =IF($A43="","",IF(D43<=F43,"Yes","No")) | H43: =IF($A43="","",H25) | I43: =IF($A43="","",F25) | J43: =IF($A43="","",G25) | K43: 3 | L43: N/A (L=1)
A44: =IF(A35="","",A35) | B44: =IF($A44="","",SUM(B35:E35)) | C44: =IF($A44="","",MAX(B35:E35)) | D44: =IF($A44="","",D26) | E44: =IF($A44="","",E26) | F44: =IF($A44="","",MAX(SUM(B33:INDEX($B35:$E35,1,MIN($E44,4))),SUM(C33:INDEX($B35:$E35,1,MIN($E44+1,4))),SUM(D33:INDEX($B35:$E35,1,MIN($E44+2,4))),E35)) | G44: =IF($A44="","",IF(D44<=F44,"Yes","No")) | H44: =IF($A44="","",H26) | I44: =IF($A44="","",F26) | J44: =IF($A44="","",G26) | K44: 3 | L44: ⚠ 3.0>2
...

Sheet Gurobi Input
A1: Gurobi Input
A2: Instance | B2: ='Formula Generator'!$B$2
A4: dish_demand | E4: recipe | I4: ingredient_params
A5: week | B5: dish | C5: demand | E5: dish | F5: ingredient | G5: amount | I5: ingredient | J5: regular_cost | K5: discount_cost | L5: min_qty | M5: shelf_life | N5: holding_cost | O5: waste_cost
A6: {=IF(INDEX('Formula Generator'!$A$6:$A$11,1)="","","Week 1")} | B6: {=IF(A6="","",INDEX('Formula Generator'!$A$6:$A$11,1))} | C6: {=IF(A6="","",INDEX('Formula Generator'!$B$6:$E$11,1,1))} | E6: {=IF(INDEX('Formula Generator'!$A$15:$A$20,1)="","",INDEX('Formula Generator'!$A$15:$A$20,1))} | F6: {=IF(E6="","",IF(INDEX('Formula Generator'!$B$14:$G$14,1,1)="","",INDEX('Formula Generator'!$B$14:$G$14,1,1)))} | G6: {=IF(OR(E6="",F6=""),"",INDEX('Formula Generator'!$B$15:$G$20,1,1))} | I6: =IF('Formula Generator'!A24="","",'Formula Generator'!A24) | J6: =IF(I6="","",'Formula Generator'!B24) | K6: =IF(I6="","",'Formula Generator'!C24) | L6: =IF(I6="","",'Formula Generator'!D24) | M6: =IF(I6="","",'Formula Generator'!E24) | N6: =IF(I6="","",'Formula Generator'!F24) | O6: =IF(I6="","",'Formula Generator'!G24)
A7: {=IF(INDEX('Formula Generator'!$A$6:$A$11,1)="","","Week 2")} | B7: {=IF(A7="","",INDEX('Formula Generator'!$A$6:$A$11,1))} | C7: {=IF(A7="","",INDEX('Formula Generator'!$B$6:$E$11,1,2))} | E7: {=IF(INDEX('Formula Generator'!$A$15:$A$20,1)="","",INDEX('Formula Generator'!$A$15:$A$20,1))} | F7: {=IF(E7="","",IF(INDEX('Formula Generator'!$B$14:$G$14,1,2)="","",INDEX('Formula Generator'!$B$14:$G$14,1,2)))} | G7: {=IF(OR(E7="",F7=""),"",INDEX('Formula Generator'!$B$15:$G$20,1,2))} | I7: =IF('Formula Generator'!A25="","",'Formula Generator'!A25) | J7: =IF(I7="","",'Formula Generator'!B25) | K7: =IF(I7="","",'Formula Generator'!C25) | L7: =IF(I7="","",'Formula Generator'!D25) | M7: =IF(I7="","",'Formula Generator'!E25) | N7: =IF(I7="","",'Formula Generator'!F25) | O7: =IF(I7="","",'Formula Generator'!G25)
A8: {=IF(INDEX('Formula Generator'!$A$6:$A$11,1)="","","Week 3")} | B8: {=IF(A8="","",INDEX('Formula Generator'!$A$6:$A$11,1))} | C8: {=IF(A8="","",INDEX('Formula Generator'!$B$6:$E$11,1,3))} | E8: {=IF(INDEX('Formula Generator'!$A$15:$A$20,1)="","",INDEX('Formula Generator'!$A$15:$A$20,1))} | F8: {=IF(E8="","",IF(INDEX('Formula Generator'!$B$14:$G$14,1,3)="","",INDEX('Formula Generator'!$B$14:$G$14,1,3)))} | G8: {=IF(OR(E8="",F8=""),"",INDEX('Formula Generator'!$B$15:$G$20,1,3))} | I8: =IF('Formula Generator'!A26="","",'Formula Generator'!A26) | J8: =IF(I8="","",'Formula Generator'!B26) | K8: =IF(I8="","",'Formula Generator'!C26) | L8: =IF(I8="","",'Formula Generator'!D26) | M8: =IF(I8="","",'Formula Generator'!E26) | N8: =IF(I8="","",'Formula Generator'!F26) | O8: =IF(I8="","",'Formula Generator'!G26)
A9: {=IF(INDEX('Formula Generator'!$A$6:$A$11,1)="","","Week 4")} | B9: {=IF(A9="","",INDEX('Formula Generator'!$A$6:$A$11,1))} | C9: {=IF(A9="","",INDEX('Formula Generator'!$B$6:$E$11,1,4))} | E9: {=IF(INDEX('Formula Generator'!$A$15:$A$20,1)="","",INDEX('Formula Generator'!$A$15:$A$20,1))} | F9: {=IF(E9="","",IF(INDEX('Formula Generator'!$B$14:$G$14,1,4)="","",INDEX('Formula Generator'!$B$14:$G$14,1,4)))} | G9: {=IF(OR(E9="",F9=""),"",INDEX('Formula Generator'!$B$15:$G$20,1,4))} | I9: =IF('Formula Generator'!A27="","",'Formula Generator'!A27) | J9: =IF(I9="","",'Formula Generator'!B27) | K9: =IF(I9="","",'Formula Generator'!C27) | L9: =IF(I9="","",'Formula Generator'!D27) | M9: =IF(I9="","",'Formula Generator'!E27) | N9: =IF(I9="","",'Formula Generator'!F27) | O9: =IF(I9="","",'Formula Generator'!G27)
A10: {=IF(INDEX('Formula Generator'!$A$6:$A$11,2)="","","Week 1")} | B10: {=IF(A10="","",INDEX('Formula Generator'!$A$6:$A$11,2))} | C10: {=IF(A10="","",INDEX('Formula Generator'!$B$6:$E$11,2,1))} | E10: {=IF(INDEX('Formula Generator'!$A$15:$A$20,1)="","",INDEX('Formula Generator'!$A$15:$A$20,1))} | F10: {=IF(E10="","",IF(INDEX('Formula Generator'!$B$14:$G$14,1,5)="","",INDEX('Formula Generator'!$B$14:$G$14,1,5)))} | G10: {=IF(OR(E10="",F10=""),"",INDEX('Formula Generator'!$B$15:$G$20,1,5))} | I10: =IF('Formula Generator'!A28="","",'Formula Generator'!A28) | J10: =IF(I10="","",'Formula Generator'!B28) | K10: =IF(I10="","",'Formula Generator'!C28) | L10: =IF(I10="","",'Formula Generator'!D28) | M10: =IF(I10="","",'Formula Generator'!E28) | N10: =IF(I10="","",'Formula Generator'!F28) | O10: =IF(I10="","",'Formula Generator'!G28)
A11: {=IF(INDEX('Formula Generator'!$A$6:$A$11,2)="","","Week 2")} | B11: {=IF(A11="","",INDEX('Formula Generator'!$A$6:$A$11,2))} | C11: {=IF(A11="","",INDEX('Formula Generator'!$B$6:$E$11,2,2))} | E11: {=IF(INDEX('Formula Generator'!$A$15:$A$20,1)="","",INDEX('Formula Generator'!$A$15:$A$20,1))} | F11: {=IF(E11="","",IF(INDEX('Formula Generator'!$B$14:$G$14,1,6)="","",INDEX('Formula Generator'!$B$14:$G$14,1,6)))} | G11: {=IF(OR(E11="",F11=""),"",INDEX('Formula Generator'!$B$15:$G$20,1,6))} | I11: =IF('Formula Generator'!A29="","",'Formula Generator'!A29) | J11: =IF(I11="","",'Formula Generator'!B29) | K11: =IF(I11="","",'Formula Generator'!C29) | L11: =IF(I11="","",'Formula Generator'!D29) | M11: =IF(I11="","",'Formula Generator'!E29) | N11: =IF(I11="","",'Formula Generator'!F29) | O11: =IF(I11="","",'Formula Generator'!G29)
A12: {=IF(INDEX('Formula Generator'!$A$6:$A$11,2)="","","Week 3")} | B12: {=IF(A12="","",INDEX('Formula Generator'!$A$6:$A$11,2))} | C12: {=IF(A12="","",INDEX('Formula Generator'!$B$6:$E$11,2,3))} | E12: {=IF(INDEX('Formula Generator'!$A$15:$A$20,2)="","",INDEX('Formula Generator'!$A$15:$A$20,2))} | F12: {=IF(E12="","",IF(INDEX('Formula Generator'!$B$14:$G$14,1,1)="","",INDEX('Formula Generator'!$B$14:$G$14,1,1)))} | G12: {=IF(OR(E12="",F12=""),"",INDEX('Formula Generator'!$B$15:$G$20,2,1))}
A13: {=IF(INDEX('Formula Generator'!$A$6:$A$11,2)="","","Week 4")} | B13: {=IF(A13="","",INDEX('Formula Generator'!$A$6:$A$11,2))} | C13: {=IF(A13="","",INDEX('Formula Generator'!$B$6:$E$11,2,4))} | E13: {=IF(INDEX('Formula Generator'!$A$15:$A$20,2)="","",INDEX('Formula Generator'!$A$15:$A$20,2))} | F13: {=IF(E13="","",IF(INDEX('Formula Generator'!$B$14:$G$14,1,2)="","",INDEX('Formula Generator'!$B$14:$G$14,1,2)))} | G13: {=IF(OR(E13="",F13=""),"",INDEX('Formula Generator'!$B$15:$G$20,2,2))}
A14: {=IF(INDEX('Formula Generator'!$A$6:$A$11,3)="","","Week 1")} | B14: {=IF(A14="","",INDEX('Formula Generator'!$A$6:$A$11,3))} | C14: {=IF(A14="","",INDEX('Formula Generator'!$B$6:$E$11,3,1))} | E14: {=IF(INDEX('Formula Generator'!$A$15:$A$20,2)="","",INDEX('Formula Generator'!$A$15:$A$20,2))} | F14: {=IF(E14="","",IF(INDEX('Formula Generator'!$B$14:$G$14,1,3)="","",INDEX('Formula Generator'!$B$14:$G$14,1,3)))} | G14: {=IF(OR(E14="",F14=""),"",INDEX('Formula Generator'!$B$15:$G$20,2,3))} | I14: ingredient_demand | M14: ingredient_summary
A15: {=IF(INDEX('Formula Generator'!$A$6:$A$11,3)="","","Week 2")} | B15: {=IF(A15="","",INDEX('Formula Generator'!$A$6:$A$11,3))} | C15: {=IF(A15="","",INDEX('Formula Generator'!$B$6:$E$11,3,2))} | E15: {=IF(INDEX('Formula Generator'!$A$15:$A$20,2)="","",INDEX('Formula Generator'!$A$15:$A$20,2))} | F15: {=IF(E15="","",IF(INDEX('Formula Generator'!$B$14:$G$14,1,4)="","",INDEX('Formula Generator'!$B$14:$G$14,1,4)))} | G15: {=IF(OR(E15="",F15=""),"",INDEX('Formula Generator'!$B$15:$G$20,2,4))} | I15: week | J15: ingredient | K15: demand | M15: ingredient | N15: total_demand | O15: max_weekly_demand | P15: recommended_M | Q15: discount_saving_pct | R15: threshold_reachable
A16: {=IF(INDEX('Formula Generator'!$A$6:$A$11,3)="","","Week 3")} | B16: {=IF(A16="","",INDEX('Formula Generator'!$A$6:$A$11,3))} | C16: {=IF(A16="","",INDEX('Formula Generator'!$B$6:$E$11,3,3))} | E16: {=IF(INDEX('Formula Generator'!$A$15:$A$20,2)="","",INDEX('Formula Generator'!$A$15:$A$20,2))} | F16: {=IF(E16="","",IF(INDEX('Formula Generator'!$B$14:$G$14,1,5)="","",INDEX('Formula Generator'!$B$14:$G$14,1,5)))} | G16: {=IF(OR(E16="",F16=""),"",INDEX('Formula Generator'!$B$15:$G$20,2,5))} | I16: {=IF(INDEX('Formula Generator'!$A$33:$A$38,1)="","","Week 1")} | J16: {=IF(I16="","",INDEX('Formula Generator'!$A$33:$A$38,1))} | K16: {=IF(I16="","",INDEX('Formula Generator'!$B$33:$E$38,1,1))} | M16: =IF('Formula Generator'!A42="","",'Formula Generator'!A42) | N16: =IF(M16="","",'Formula Generator'!B42) | O16: =IF(M16="","",'Formula Generator'!C42) | P16: =IF(M16="","",'Formula Generator'!F42) | Q16: =IF(M16="","",'Formula Generator'!H42) | R16: =IF(M16="","",'Formula Generator'!G42)
A17: {=IF(INDEX('Formula Generator'!$A$6:$A$11,3)="","","Week 4")} | B17: {=IF(A17="","",INDEX('Formula Generator'!$A$6:$A$11,3))} | C17: {=IF(A17="","",INDEX('Formula Generator'!$B$6:$E$11,3,4))} | E17: {=IF(INDEX('Formula Generator'!$A$15:$A$20,2)="","",INDEX('Formula Generator'!$A$15:$A$20,2))} | F17: {=IF(E17="","",IF(INDEX('Formula Generator'!$B$14:$G$14,1,6)="","",INDEX('Formula Generator'!$B$14:$G$14,1,6)))} | G17: {=IF(OR(E17="",F17=""),"",INDEX('Formula Generator'!$B$15:$G$20,2,6))} | I17: {=IF(INDEX('Formula Generator'!$A$33:$A$38,1)="","","Week 2")} | J17: {=IF(I17="","",INDEX('Formula Generator'!$A$33:$A$38,1))} | K17: {=IF(I17="","",INDEX('Formula Generator'!$B$33:$E$38,1,2))} | M17: =IF('Formula Generator'!A43="","",'Formula Generator'!A43) | N17: =IF(M17="","",'Formula Generator'!B43) | O17: =IF(M17="","",'Formula Generator'!C43) | P17: =IF(M17="","",'Formula Generator'!F43) | Q17: =IF(M17="","",'Formula Generator'!H43) | R17: =IF(M17="","",'Formula Generator'!G43)
A18: {=IF(INDEX('Formula Generator'!$A$6:$A$11,4)="","","Week 1")} | B18: {=IF(A18="","",INDEX('Formula Generator'!$A$6:$A$11,4))} | C18: {=IF(A18="","",INDEX('Formula Generator'!$B$6:$E$11,4,1))} | E18: {=IF(INDEX('Formula Generator'!$A$15:$A$20,3)="","",INDEX('Formula Generator'!$A$15:$A$20,3))} | F18: {=IF(E18="","",IF(INDEX('Formula Generator'!$B$14:$G$14,1,1)="","",INDEX('Formula Generator'!$B$14:$G$14,1,1)))} | G18: {=IF(OR(E18="",F18=""),"",INDEX('Formula Generator'!$B$15:$G$20,3,1))} | I18: {=IF(INDEX('Formula Generator'!$A$33:$A$38,1)="","","Week 3")} | J18: {=IF(I18="","",INDEX('Formula Generator'!$A$33:$A$38,1))} | K18: {=IF(I18="","",INDEX('Formula Generator'!$B$33:$E$38,1,3))} | M18: =IF('Formula Generator'!A44="","",'Formula Generator'!A44) | N18: =IF(M18="","",'Formula Generator'!B44) | O18: =IF(M18="","",'Formula Generator'!C44) | P18: =IF(M18="","",'Formula Generator'!F44) | Q18: =IF(M18="","",'Formula Generator'!H44) | R18: =IF(M18="","",'Formula Generator'!G44)
A19: {=IF(INDEX('Formula Generator'!$A$6:$A$11,4)="","","Week 2")} | B19: {=IF(A19="","",INDEX('Formula Generator'!$A$6:$A$11,4))} | C19: {=IF(A19="","",INDEX('Formula Generator'!$B$6:$E$11,4,2))} | E19: {=IF(INDEX('Formula Generator'!$A$15:$A$20,3)="","",INDEX('Formula Generator'!$A$15:$A$20,3))} | F19: {=IF(E19="","",IF(INDEX('Formula Generator'!$B$14:$G$14,1,2)="","",INDEX('Formula Generator'!$B$14:$G$14,1,2)))} | G19: {=IF(OR(E19="",F19=""),"",INDEX('Formula Generator'!$B$15:$G$20,3,2))} | I19: {=IF(INDEX('Formula Generator'!$A$33:$A$38,1)="","","Week 4")} | J19: {=IF(I19="","",INDEX('Formula Generator'!$A$33:$A$38,1))} | K19: {=IF(I19="","",INDEX('Formula Generator'!$B$33:$E$38,1,4))} | M19: =IF('Formula Generator'!A45="","",'Formula Generator'!A45) | N19: =IF(M19="","",'Formula Generator'!B45) | O19: =IF(M19="","",'Formula Generator'!C45) | P19: =IF(M19="","",'Formula Generator'!F45) | Q19: =IF(M19="","",'Formula Generator'!H45) | R19: =IF(M19="","",'Formula Generator'!G45)
A20: {=IF(INDEX('Formula Generator'!$A$6:$A$11,4)="","","Week 3")} | B20: {=IF(A20="","",INDEX('Formula Generator'!$A$6:$A$11,4))} | C20: {=IF(A20="","",INDEX('Formula Generator'!$B$6:$E$11,4,3))} | E20: {=IF(INDEX('Formula Generator'!$A$15:$A$20,3)="","",INDEX('Formula Generator'!$A$15:$A$20,3))} | F20: {=IF(E20="","",IF(INDEX('Formula Generator'!$B$14:$G$14,1,3)="","",INDEX('Formula Generator'!$B$14:$G$14,1,3)))} | G20: {=IF(OR(E20="",F20=""),"",INDEX('Formula Generator'!$B$15:$G$20,3,3))} | I20: {=IF(INDEX('Formula Generator'!$A$33:$A$38,2)="","","Week 1")} | J20: {=IF(I20="","",INDEX('Formula Generator'!$A$33:$A$38,2))} | K20: {=IF(I20="","",INDEX('Formula Generator'!$B$33:$E$38,2,1))} | M20: =IF('Formula Generator'!A46="","",'Formula Generator'!A46) | N20: =IF(M20="","",'Formula Generator'!B46) | O20: =IF(M20="","",'Formula Generator'!C46) | P20: =IF(M20="","",'Formula Generator'!F46) | Q20: =IF(M20="","",'Formula Generator'!H46) | R20: =IF(M20="","",'Formula Generator'!G46)
A21: {=IF(INDEX('Formula Generator'!$A$6:$A$11,4)="","","Week 4")} | B21: {=IF(A21="","",INDEX('Formula Generator'!$A$6:$A$11,4))} | C21: {=IF(A21="","",INDEX('Formula Generator'!$B$6:$E$11,4,4))} | E21: {=IF(INDEX('Formula Generator'!$A$15:$A$20,3)="","",INDEX('Formula Generator'!$A$15:$A$20,3))} | F21: {=IF(E21="","",IF(INDEX('Formula Generator'!$B$14:$G$14,1,4)="","",INDEX('Formula Generator'!$B$14:$G$14,1,4)))} | G21: {=IF(OR(E21="",F21=""),"",INDEX('Formula Generator'!$B$15:$G$20,3,4))} | I21: {=IF(INDEX('Formula Generator'!$A$33:$A$38,2)="","","Week 2")} | J21: {=IF(I21="","",INDEX('Formula Generator'!$A$33:$A$38,2))} | K21: {=IF(I21="","",INDEX('Formula Generator'!$B$33:$E$38,2,2))} | M21: =IF('Formula Generator'!A47="","",'Formula Generator'!A47) | N21: =IF(M21="","",'Formula Generator'!B47) | O21: =IF(M21="","",'Formula Generator'!C47) | P21: =IF(M21="","",'Formula Generator'!F47) | Q21: =IF(M21="","",'Formula Generator'!H47) | R21: =IF(M21="","",'Formula Generator'!G47)
A22: {=IF(INDEX('Formula Generator'!$A$6:$A$11,5)="","","Week 1")} | B22: {=IF(A22="","",INDEX('Formula Generator'!$A$6:$A$11,5))} | C22: {=IF(A22="","",INDEX('Formula Generator'!$B$6:$E$11,5,1))} | E22: {=IF(INDEX('Formula Generator'!$A$15:$A$20,3)="","",INDEX('Formula Generator'!$A$15:$A$20,3))} | F22: {=IF(E22="","",IF(INDEX('Formula Generator'!$B$14:$G$14,1,5)="","",INDEX('Formula Generator'!$B$14:$G$14,1,5)))} | G22: {=IF(OR(E22="",F22=""),"",INDEX('Formula Generator'!$B$15:$G$20,3,5))} | I22: {=IF(INDEX('Formula Generator'!$A$33:$A$38,2)="","","Week 3")} | J22: {=IF(I22="","",INDEX('Formula Generator'!$A$33:$A$38,2))} | K22: {=IF(I22="","",INDEX('Formula Generator'!$B$33:$E$38,2,3))}
A23: {=IF(INDEX('Formula Generator'!$A$6:$A$11,5)="","","Week 2")} | B23: {=IF(A23="","",INDEX('Formula Generator'!$A$6:$A$11,5))} | C23: {=IF(A23="","",INDEX('Formula Generator'!$B$6:$E$11,5,2))} | E23: {=IF(INDEX('Formula Generator'!$A$15:$A$20,3)="","",INDEX('Formula Generator'!$A$15:$A$20,3))} | F23: {=IF(E23="","",IF(INDEX('Formula Generator'!$B$14:$G$14,1,6)="","",INDEX('Formula Generator'!$B$14:$G$14,1,6)))} | G23: {=IF(OR(E23="",F23=""),"",INDEX('Formula Generator'!$B$15:$G$20,3,6))} | I23: {=IF(INDEX('Formula Generator'!$A$33:$A$38,2)="","","Week 4")} | J23: {=IF(I23="","",INDEX('Formula Generator'!$A$33:$A$38,2))} | K23: {=IF(I23="","",INDEX('Formula Generator'!$B$33:$E$38,2,4))}
A24: {=IF(INDEX('Formula Generator'!$A$6:$A$11,5)="","","Week 3")} | B24: {=IF(A24="","",INDEX('Formula Generator'!$A$6:$A$11,5))} | C24: {=IF(A24="","",INDEX('Formula Generator'!$B$6:$E$11,5,3))} | E24: {=IF(INDEX('Formula Generator'!$A$15:$A$20,4)="","",INDEX('Formula Generator'!$A$15:$A$20,4))} | F24: {=IF(E24="","",IF(INDEX('Formula Generator'!$B$14:$G$14,1,1)="","",INDEX('Formula Generator'!$B$14:$G$14,1,1)))} | G24: {=IF(OR(E24="",F24=""),"",INDEX('Formula Generator'!$B$15:$G$20,4,1))} | I24: {=IF(INDEX('Formula Generator'!$A$33:$A$38,3)="","","Week 1")} | J24: {=IF(I24="","",INDEX('Formula Generator'!$A$33:$A$38,3))} | K24: {=IF(I24="","",INDEX('Formula Generator'!$B$33:$E$38,3,1))}
A25: {=IF(INDEX('Formula Generator'!$A$6:$A$11,5)="","","Week 4")} | B25: {=IF(A25="","",INDEX('Formula Generator'!$A$6:$A$11,5))} | C25: {=IF(A25="","",INDEX('Formula Generator'!$B$6:$E$11,5,4))} | E25: {=IF(INDEX('Formula Generator'!$A$15:$A$20,4)="","",INDEX('Formula Generator'!$A$15:$A$20,4))} | F25: {=IF(E25="","",IF(INDEX('Formula Generator'!$B$14:$G$14,1,2)="","",INDEX('Formula Generator'!$B$14:$G$14,1,2)))} | G25: {=IF(OR(E25="",F25=""),"",INDEX('Formula Generator'!$B$15:$G$20,4,2))} | I25: {=IF(INDEX('Formula Generator'!$A$33:$A$38,3)="","","Week 2")} | J25: {=IF(I25="","",INDEX('Formula Generator'!$A$33:$A$38,3))} | K25: {=IF(I25="","",INDEX('Formula Generator'!$B$33:$E$38,3,2))}
A26: {=IF(INDEX('Formula Generator'!$A$6:$A$11,6)="","","Week 1")} | B26: {=IF(A26="","",INDEX('Formula Generator'!$A$6:$A$11,6))} | C26: {=IF(A26="","",INDEX('Formula Generator'!$B$6:$E$11,6,1))} | E26: {=IF(INDEX('Formula Generator'!$A$15:$A$20,4)="","",INDEX('Formula Generator'!$A$15:$A$20,4))} | F26: {=IF(E26="","",IF(INDEX('Formula Generator'!$B$14:$G$14,1,3)="","",INDEX('Formula Generator'!$B$14:$G$14,1,3)))} | G26: {=IF(OR(E26="",F26=""),"",INDEX('Formula Generator'!$B$15:$G$20,4,3))} | I26: {=IF(INDEX('Formula Generator'!$A$33:$A$38,3)="","","Week 3")} | J26: {=IF(I26="","",INDEX('Formula Generator'!$A$33:$A$38,3))} | K26: {=IF(I26="","",INDEX('Formula Generator'!$B$33:$E$38,3,3))}
